web/sample.jsonl
{"t":"meta","ts_ns":1781197833181895272,"source":"binance","feed":"ws","symbols":["BTCUSDT","ETHUSDT"]}
{"t":"status","ts_ns":1781197835377991123,"sym":"BTCUSDT","mid":62530.55,"bid":62530.55,"ask":62530.55,"pos_btc":0.000000,"cash":0.00,"equity":0.00,"fills":0}
{"t":"status","ts_ns":1781197835378035831,"sym":"ETHUSDT","mid":1640.32,"bid":1640.32,"ask":1640.32,"pos_btc":0.000000,"cash":0.00,"equity":0.00,"fills":0}
{"t":"status","ts_ns":1781197837378148573,"sym":"BTCUSDT","mid":62530.05,"bid":62530.05,"ask":62530.05,"pos_btc":0.000000,"cash":0.00,"equity":0.00,"fills":0}
{"t":"status","ts_ns":1781197837378184455,"sym":"ETHUSDT","mid":1640.08,"bid":1640.08,"ask":1640.08,"pos_btc":0.000000,"cash":0.00,"equity":0.00,"fills":0}
{"t":"status","ts_ns":1781197842354201552,"sym":"BTCUSDT","mid":62520.85,"bid":62520.85,"ask":62520.85,"pos_btc":0.000000,"cash":0.00,"equity":0.00,"fills":0}
{"t":"status","ts_ns":1781197842354238031,"sym":"ETHUSDT","mid":1640.04,"bid":1640.04,"ask":1640.04,"pos_btc":0.000000,"cash":0.00,"equity":0.00,"fills":0}
{"t":"fill","ts_ns":1781197843876622069,"sym":"ETHUSDT","side":"SELL","px":1640.12,"qty":0.001000,"lat_us":2.038}
{"t":"fill","ts_ns":1781197843876672710,"sym":"ETHUSDT","side":"SELL","px":1640.18,"qty":0.001000,"lat_us":12.233}
{"t":"fill","ts_ns":1781197843876708097,"sym":"ETHUSDT","side":"SELL","px":1640.18,"qty":0.001000,"lat_us":0.954}
{"t":"fill","ts_ns":1781197843877203487,"sym":"ETHUSDT","side":"BUY","px":1640.26,"qty":0.001000,"lat_us":1.037}
{"t":"fill","ts_ns":1781197844002360022,"sym":"ETHUSDT","side":"SELL","px":1640.51,"qty":0.001000,"lat_us":6.107}
{"t":"fill","ts_ns":1781197844048543477,"sym":"BTCUSDT","side":"SELL","px":62540.90,"qty":0.001000,"lat_us":3.452}
{"t":"status","ts_ns":1781197844354381939,"sym":"BTCUSDT","mid":62541.05,"bid":62541.05,"ask":62541.05,"pos_btc":-0.001000,"cash":62.54,"equity":0.00,"fills":1}
{"t":"status","ts_ns":1781197844354427437,"sym":"ETHUSDT","mid":1640.67,"bid":1640.67,"ask":1640.67,"pos_btc":-0.003000,"cash":4.92,"equity":0.00,"fills":5}
{"t":"status","ts_ns":1781197846354525919,"sym":"BTCUSDT","mid":62541.25,"bid":62541.25,"ask":62541.25,"pos_btc":-0.001000,"cash":62.54,"equity":0.00,"fills":1}
{"t":"status","ts_ns":1781197846354564896,"sym":"ETHUSDT","mid":1640.67,"bid":1640.67,"ask":1640.67,"pos_btc":-0.003000,"cash":4.92,"equity":0.00,"fills":5}
{"t":"status","ts_ns":1781197848354721286,"sym":"BTCUSDT","mid":62541.25,"bid":62541.25,"ask":62541.25,"pos_btc":-0.001000,"cash":62.54,"equity":0.00,"fills":1}
{"t":"status","ts_ns":1781197848354767537,"sym":"ETHUSDT","mid":1640.62,"bid":1640.62,"ask":1640.62,"pos_btc":-0.003000,"cash":4.92,"equity":0.00,"fills":5}
{"t":"status","ts_ns":1781197850354895236,"sym":"BTCUSDT","mid":62540.75,"bid":62540.75,"ask":62540.75,"pos_btc":-0.001000,"cash":62.54,"equity":0.00,"fills":1}
{"t":"status","ts_ns":1781197850354959800,"sym":"ETHUSDT","mid":1640.55,"bid":1640.55,"ask":1640.55,"pos_btc":-0.003000,"cash":4.92,"equity":0.00,"fills":5}
{"t":"status","ts_ns":1781197852355141352,"sym":"BTCUSDT","mid":62530.45,"bid":62530.45,"ask":62530.45,"pos_btc":-0.001000,"cash":62.54,"equity":0.01,"fills":1}
{"t":"status","ts_ns":1781197852355206044,"sym":"ETHUSDT","mid":1640.26,"bid":1640.26,"ask":1640.26,"pos_btc":-0.003000,"cash":4.92,"equity":0.00,"fills":5}
{"t":"status","ts_ns":1781197854355315990,"sym":"BTCUSDT","mid":62520.95,"bid":62520.95,"ask":62520.95,"pos_btc":-0.001000,"cash":62.54,"equity":0.02,"fills":1}
{"t":"status","ts_ns":1781197854355370360,"sym":"ETHUSDT","mid":1640.00,"bid":1640.00,"ask":1640.00,"pos_btc":-0.003000,"cash":4.92,"equity":0.00,"fills":5}
{"t":"fill","ts_ns":1781197854899751689,"sym":"ETHUSDT","side":"SELL","px":1640.12,"qty":0.001000,"lat_us":2.075}
{"t":"fill","ts_ns":1781197856004873549,"sym":"ETHUSDT","side":"BUY","px":1640.03,"qty":0.001000,"lat_us":7.816}
{"t":"status","ts_ns":1781197856355477146,"sym":"BTCUSDT","mid":62520.95,"bid":62520.95,"ask":62520.95,"pos_btc":-0.001000,"cash":62.54,"equity":0.02,"fills":1}
{"t":"status","ts_ns":1781197856355512495,"sym":"ETHUSDT","mid":1640.02,"bid":1640.02,"ask":1640.02,"pos_btc":-0.003000,"cash":4.92,"equity":0.00,"fills":7}
{"t":"status","ts_ns":1781197858355669867,"sym":"BTCUSDT","mid":62520.95,"bid":62520.95,"ask":62520.95,"pos_btc":-0.001000,"cash":62.54,"equity":0.02,"fills":1}
{"t":"status","ts_ns":1781197858355721601,"sym":"ETHUSDT","mid":1640.02,"bid":1640.02,"ask":1640.02,"pos_btc":-0.003000,"cash":4.92,"equity":0.00,"fills":7}
{"t":"status","ts_ns":1781197860355854637,"sym":"BTCUSDT","mid":62518.75,"bid":62518.75,"ask":62518.75,"pos_btc":-0.001000,"cash":62.54,"equity":0.03,"fills":1}
{"t":"status","ts_ns":1781197860355891410,"sym":"ETHUSDT","mid":1639.90,"bid":1639.90,"ask":1639.90,"pos_btc":-0.003000,"cash":4.92,"equity":0.01,"fills":7}
{"t":"status","ts_ns":1781197862355988477,"sym":"BTCUSDT","mid":62504.95,"bid":62504.95,"ask":62504.95,"pos_btc":-0.001000,"cash":62.54,"equity":0.04,"fills":1}
{"t":"status","ts_ns":1781197862356030788,"sym":"ETHUSDT","mid":1639.63,"bid":1639.63,"ask":1639.63,"pos_btc":-0.003000,"cash":4.92,"equity":0.01,"fills":7}
{"t":"status","ts_ns":1781197864356149771,"sym":"BTCUSDT","mid":62501.15,"bid":62501.15,"ask":62501.15,"pos_btc":-0.001000,"cash":62.54,"equity":0.04,"fills":1}
{"t":"status","ts_ns":1781197864356190502,"sym":"ETHUSDT","mid":1639.50,"bid":1639.50,"ask":1639.50,"pos_btc":-0.003000,"cash":4.92,"equity":0.01,"fills":7}
{"t":"fill","ts_ns":1781197864392095721,"sym":"ETHUSDT","side":"BUY","px":1639.45,"qty":0.001000,"lat_us":11.562}
{"t":"fill","ts_ns":1781197864393041913,"sym":"ETHUSDT","side":"BUY","px":1639.37,"qty":0.001000,"lat_us":1.497}
{"t":"status","ts_ns":1781197866356314122,"sym":"BTCUSDT","mid":62501.15,"bid":62501.15,"ask":62501.15,"pos_btc":-0.001000,"cash":62.54,"equity":0.04,"fills":1}
{"t":"status","ts_ns":1781197866356350280,"sym":"ETHUSDT","mid":1639.45,"bid":1639.45,"ask":1639.45,"pos_btc":-0.001000,"cash":1.66,"equity":0.03,"fills":9}
{"t":"status","ts_ns":1781197868356452313,"sym":"BTCUSDT","mid":62500.05,"bid":62500.05,"ask":62500.05,"pos_btc":-0.001000,"cash":62.54,"equity":0.04,"fills":1}
{"t":"status","ts_ns":1781197868356494321,"sym":"ETHUSDT","mid":1639.45,"bid":1639.45,"ask":1639.45,"pos_btc":-0.001000,"cash":1.66,"equity":0.03,"fills":9}
{"t":"fill","ts_ns":1781197870319064631,"sym":"BTCUSDT","side":"SELL","px":62504.00,"qty":0.001000,"lat_us":1.743}
{"t":"status","ts_ns":1781197870356587038,"sym":"BTCUSDT","mid":62504.05,"bid":62504.05,"ask":62504.05,"pos_btc":-0.002000,"cash":125.04,"equity":0.04,"fills":2}
{"t":"status","ts_ns":1781197870356621818,"sym":"ETHUSDT","mid":1639.51,"bid":1639.51,"ask":1639.51,"pos_btc":-0.001000,"cash":1.66,"equity":0.03,"fills":9}
{"t":"status","ts_ns":1781197872356724539,"sym":"BTCUSDT","mid":62504.05,"bid":62504.05,"ask":62504.05,"pos_btc":-0.002000,"cash":125.04,"equity":0.04,"fills":2}
{"t":"status","ts_ns":1781197872356764022,"sym":"ETHUSDT","mid":1639.58,"bid":1639.58,"ask":1639.58,"pos_btc":-0.001000,"cash":1.66,"equity":0.03,"fills":9}
{"t":"fill","ts_ns":1781197873229155452,"sym":"ETHUSDT","side":"SELL","px":1639.70,"qty":0.001000,"lat_us":2.516}
{"t":"fill","ts_ns":1781197873918256023,"sym":"ETHUSDT","side":"BUY","px":1639.61,"qty":0.001000,"lat_us":128.053}
{"t":"status","ts_ns":1781197874356926945,"sym":"BTCUSDT","mid":62511.25,"bid":62511.25,"ask":62511.25,"pos_btc":-0.002000,"cash":125.04,"equity":0.02,"fills":2}
{"t":"status","ts_ns":1781197874357025583,"sym":"ETHUSDT","mid":1639.60,"bid":1639.60,"ask":1639.60,"pos_btc":-0.001000,"cash":1.66,"equity":0.03,"fills":11}
{"t":"status","ts_ns":1781197876357187588,"sym":"BTCUSDT","mid":62511.25,"bid":62511.25,"ask":62511.25,"pos_btc":-0.002000,"cash":125.04,"equity":0.02,"fills":2}
{"t":"status","ts_ns":1781197876357246054,"sym":"ETHUSDT","mid":1639.67,"bid":1639.67,"ask":1639.67,"pos_btc":-0.001000,"cash":1.66,"equity":0.03,"fills":11}
{"t":"status","ts_ns":1781197878357333768,"sym":"BTCUSDT","mid":62513.95,"bid":62513.95,"ask":62513.95,"pos_btc":-0.002000,"cash":125.04,"equity":0.02,"fills":2}
